Workbook

Sheet Disbursement
A1: Borrower: | B1: Seven Circle (Bangladesh) Ltd.
A2: Currency: | B2: BDT
A3: Type | B3: IDCOL Loan
A4: Source :
A7: Disbursement Number | B7: Disbursement Date | C7: Disbursement | D7: Cumulative Disbursement | E7: Source
A8: 1 (part-1) | B8: 43648 | C8: 580000000 | D8: =C8 -> 580000000 | E8: IDCOL Current Account
A9: 1 (part-2) | B9: 43648 | C9: 120000000 | D9: =D8+C9 -> 700000000 | E9: IDCOL Current Account
A10: 2 | B10: 43662 | C10: 1000000000 | D10: =D9+C10 -> 1700000000 | E10: IDCOL Current Account

Sheet Summary
B1: ='Accrual_SCBL '!B23 -> 43678 | C1: ='Accrual_SCBL '!C23 -> 43709 | D1: ='Accrual_SCBL '!D23 -> 43739 | E1: ='Accrual_SCBL '!E23 -> 43770 | F1: ='Accrual_SCBL '!F23 -> 43800 | G1: ='Accrual_SCBL '!G23 -> 43831 | H1: ='Accrual_SCBL '!H23 -> 43862 | I1: ='Accrual_SCBL '!I23 -> 43891 | ... DQ1: ='Accrual_SCBL '!DQ23 -> 47300
A2: Principal
A3: Opening balance | B3: ='Accrual_SCBL '!B24 -> 1700000000 | C3: ='Accrual_SCBL '!C24 -> 1700000000 | D3: ='Accrual_SCBL '!D24 -> 1700000000 | E3: ='Accrual_SCBL '!E24 -> 1700000000 | F3: ='Accrual_SCBL '!F24 -> 1700000000 | G3: ='Accrual_SCBL '!G24 -> 1700000000 | H3: ='Accrual_SCBL '!H24 -> 1700000000 | I3: ='Accrual_SCBL '!I24 -> 1700000000 | ... Q3: ='Accrual_SCBL '!Q24 -> 1700000000 | R3: =Q3 -> 1700000000 | S3: =R3 -> 1700000000 | T3: =S3 -> 1700000000 | U3: =T3 -> 1700000000 | V3: =U3 -> 1700000000 | W3: =V3 -> 1700000000 | X3: =W3 -> 1700000000 | Y3: =X3 -> 1700000000 | ... DQ3: =DP3 -> 1700000000
A4: Repayment due | B4: ='Accrual_SCBL '!B28 -> 0 | C4: ='Accrual_SCBL '!C28 -> 0 | D4: ='Accrual_SCBL '!D28 -> 0 | E4: ='Accrual_SCBL '!E28 -> 0 | F4: ='Accrual_SCBL '!F28 -> 0 | G4: ='Accrual_SCBL '!G28 -> 0 | H4: ='Accrual_SCBL '!H28 -> 0 | I4: ='Accrual_SCBL '!I28 -> 0 | ... DQ4: ='Accrual_SCBL '!DQ28 -> 1700000000
A5: Loan Repayment | B5: =B22 -> 0 | C5: =C22 -> 0 | D5: =D22 -> 0 | E5: =E22 -> 0 | F5: =F22 -> 0 | G5: =G22 -> 0 | H5: =H22 -> 0 | I5: =I22 -> 0 | ... DQ5: =DQ22 -> 1700000000
A6: Repayment overdue | B6: =IF((B4-B5)>0,(B4-B5),0) -> 0 | C6: =IF((C4-C5)>0,(C4-C5),0) -> 0 | D6: =IF((D4-D5)>0,(D4-D5),0) -> 0 | E6: =IF((E4-E5)>0,(E4-E5),0) -> 0 | F6: =IF((F4-F5)>0,(F4-F5),0) -> 0 | G6: =IF((G4-G5)>0,(G4-G5),0) -> 0 | H6: =IF((H4-H5)>0,(H4-H5),0) -> 0 | I6: =IF((I4-I5)>0,(I4-I5),0) -> 0 | ... DQ6: =IF((DQ4-DQ5)>0,(DQ4-DQ5),0) -> 0
A7: Loan outstanding | B7: =B3-B5 -> 1700000000 | C7: =C3-C5 -> 1700000000 | D7: =D3-D5 -> 1700000000 | E7: =E3-E5 -> 1700000000 | F7: =F3-F5 -> 1700000000 | G7: =G3-G5 -> 1700000000 | H7: =H3-H5 -> 1700000000 | I7: =I3-I5 -> 1700000000 | ... DQ7: =DQ3-DQ5 -> 0
A8: Interest
A9: Interest accrued | B9: ='Accrual_SCBL '!B26 -> 9763888.9 | C9: ='Accrual_SCBL '!C26 -> 23670833 | D9: ='Accrual_SCBL '!D26 -> 37129167 | E9: ='Accrual_SCBL '!E26 -> 51036111 | F9: ='Accrual_SCBL '!F26 -> 64494444 | G9: ='Accrual_SCBL '!G26 -> 78401389 | H9: ='Accrual_SCBL '!H26 -> 92308333 | I9: ='Accrual_SCBL '!I26 -> 1.0531806e+08 | ... DQ9: ='Accrual_SCBL '!DQ26 -> 9.1051552e+08
A10: Interest due | B10: 0 | C10: =B10 -> 0 | D10: =SCBL_Loan!$B$31 -> 29951389 | E10: =D10 -> 29951389 | F10: =E10 -> 29951389 | G10: =SCBL_Loan!$C$31 -> 70775000 | H10: =G10 -> 70775000 | I10: =H10 -> 70775000 | J10: =SCBL_Loan!$D$31 -> 1.1159861e+08 | K10: =J10 -> 1.1159861e+08 | L10: =K10 -> 1.1159861e+08 | M10: =SCBL_Loan!$E$31 -> 1.5287083e+08 | N10: =M10 -> 1.5287083e+08 | O10: =N10 -> 1.5287083e+08 | P10: =SCBL_Loan!$F$31 -> 1.9336389e+08 | Q10: =P10 -> 1.9336389e+08 | R10: =Q10 -> 1.9336389e+08 | S10: =SCBL_Loan!$G$31 -> 2.3203889e+08 | T10: =S10 -> 2.3203889e+08 | U10: =T10 -> 2.3203889e+08 | V10: =SCBL_Loan!$H$31 -> 2.7028889e+08 | W10: =V10 -> 2.7028889e+08 | X10: =W10 -> 2.7028889e+08 | Y10: =SCBL_Loan!$I$31 -> 3.0823153e+08 | Z10: =Y10 -> 3.0823153e+08 | AA10: =Z10 -> 3.0823153e+08 | AB10: =SCBL_Loan!$J$31 -> 3.4501681e+08 | AC10: =AB10 -> 3.4501681e+08 | AD10: =AC10 -> 3.4501681e+08 | AE10: =SCBL_Loan!$K$31 -> 3.802652e+08 | AF10: =AE10 -> 3.802652e+08 | AG10: =AF10 -> 3.802652e+08 | AH10: =SCBL_Loan!$L$31 -> 4.140017e+08 | AI10: =AH10 -> 4.140017e+08 | AJ10: =AI10 -> 4.140017e+08 | AK10: =SCBL_Loan!$M$31 -> 4.4733836e+08 | AL10: =AK10 -> 4.4733836e+08 | AM10: =AL10 -> 4.4733836e+08 | AN10: =SCBL_Loan!$N$31 -> 4.7952548e+08 | AO10: =AN10 -> 4.7952548e+08 | AP10: =AO10 -> 4.7952548e+08 | AQ10: =SCBL_Loan!$O$31 -> 5.102257e+08 | AR10: =AQ10 -> 5.102257e+08 | AS10: =AR10 -> 5.102257e+08 | AT10: =SCBL_Loan!$P$31 -> 5.39464e+08 | AU10: =AT10 -> 5.39464e+08 | AV10: =AU10 -> 5.39464e+08 | AW10: =SCBL_Loan!$Q$31 -> 5.682025e+08 | AX10: =AW10 -> 5.682025e+08 | AY10: =AX10 -> 5.682025e+08 | AZ10: =SCBL_Loan!$R$31 -> 5.9549158e+08 | BA10: =AZ10 -> 5.9549158e+08 | BB10: =BA10 -> 5.9549158e+08 | BC10: =SCBL_Loan!$S$31 -> 6.2164361e+08 | BD10: =BC10 -> 6.2164361e+08 | BE10: =BD10 -> 6.2164361e+08 | BF10: =SCBL_Loan!$T$31 -> 6.466586e+08 | BG10: =BF10 -> 6.466586e+08 | BH10: =BG10 -> 6.466586e+08 | BI10: =SCBL_Loan!$U$31 -> 6.7053655e+08 | BJ10: =BI10 -> 6.7053655e+08 | BK10: =BJ10 -> 6.7053655e+08 | BL10: =SCBL_Loan!$V$31 -> 6.9402715e+08 | BM10: =BL10 -> 6.9402715e+08 | BN10: =BM10 -> 6.9402715e+08 | BO10: =SCBL_Loan!$W$31 -> 7.15631e+08 | BP10: =BO10 -> 7.15631e+08 | BQ10: =BP10 -> 7.15631e+08 | BR10: =SCBL_Loan!$X$31 -> 7.3542308e+08 | BS10: =BR10 -> 7.3542308e+08 | BT10: =BS10 -> 7.3542308e+08 | BU10: =SCBL_Loan!$Y$31 -> 7.5539009e+08 | BV10: =BU10 -> 7.5539009e+08 | BW10: =BV10 -> 7.5539009e+08 | BX10: =SCBL_Loan!$Z$31 -> 7.7378273e+08 | BY10: =BX10 -> 7.7378273e+08 | BZ10: =BY10 -> 7.7378273e+08 | CA10: =SCBL_Loan!$AA$31 -> 7.9083841e+08 | CB10: =CA10 -> 7.9083841e+08 | CC10: =CB10 -> 7.9083841e+08 | CD10: =SCBL_Loan!$AB$31 -> 8.0658211e+08 | CE10: =CD10 -> 8.0658211e+08 | CF10: =CE10 -> 8.0658211e+08 | CG10: =SCBL_Loan!$AC$31 -> 8.2152613e+08 | CH10: =CG10 -> 8.2152613e+08 | CI10: =CH10 -> 8.2152613e+08 | CJ10: =SCBL_Loan!$AD$31 -> 8.3532061e+08 | CK10: =CJ10 -> 8.3532061e+08 | CL10: =CK10 -> 8.3532061e+08 | CM10: =SCBL_Loan!$AE$31 -> 8.478281e+08 | CN10: =CM10 -> 8.478281e+08 | CO10: =CN10 -> 8.478281e+08 | CP10: =SCBL_Loan!$AF$31 -> 8.590736e+08 | CQ10: =CP10 -> 8.590736e+08 | CR10: =CQ10 -> 8.590736e+08 | CS10: =SCBL_Loan!$AG$31 -> 8.6941946e+08 | CT10: =CS10 -> 8.6941946e+08 | CU10: =CT10 -> 8.6941946e+08 | CV10: =SCBL_Loan!$AH$31 -> 8.7861578e+08 | CW10: =CV10 -> 8.7861578e+08 | CX10: =CW10 -> 8.7861578e+08 | CY10: =SCBL_Loan!$AI$31 -> 8.865751e+08 | CZ10: =CY10 -> 8.865751e+08 | DA10: =CZ10 -> 8.865751e+08 | DB10: =SCBL_Loan!$AJ$31 -> 8.9339737e+08 | DC10: =DB10 -> 8.9339737e+08 | DD10: =DC10 -> 8.9339737e+08 | DE10: =SCBL_Loan!$AK$31 -> 8.9914507e+08 | DF10: =DE10 -> 8.9914507e+08 | DG10: =DF10 -> 8.9914507e+08 | DH10: =SCBL_Loan!$AL$31 -> 9.0369325e+08 | DI10: =DH10 -> 9.0369325e+08 | DJ10: =DI10 -> 9.0369325e+08 | DK10: =SCBL_Loan!$AM$31 -> 9.0710438e+08 | DL10: =DK10 -> 9.0710438e+08 | DM10: =DL10 -> 9.0710438e+08 | DN10: =SCBL_Loan!$AN$31 -> 9.0937847e+08 | DO10: =DN10 -> 9.0937847e+08 | DP10: =DO10 -> 9.0937847e+08 | DQ10: =SCBL_Loan!$AO$31 -> 9.1051552e+08
A11: interest received | B11: =B26 -> 0 | C11: =C26 -> 0 | D11: =D26 -> 29951389 | E11: =E26 -> 29951389 | F11: =F26 -> 29951389 | G11: =G26 -> 70775000 | H11: =H26 -> 70775000 | I11: =I26 -> 70775000 | ... DQ11: =DQ26 -> 9.1051552e+08
A12: Interest overdue | B12: =IF((B10-B11)>0,(B10-B11),0) -> 0 | C12: =IF((C10-C11)>0,(C10-C11),0) -> 0 | D12: =IF((D10-D11)>0,(D10-D11),0) -> 0 | E12: =IF((E10-E11)>0,(E10-E11),0) -> 0 | F12: =IF((F10-F11)>0,(F10-F11),0) -> 0 | G12: =IF((G10-G11)>0,(G10-G11),0) -> 0 | H12: =IF((H10-H11)>0,(H10-H11),0) -> 0 | I12: =IF((I10-I11)>0,(I10-I11),0) -> 0 | ... DQ12: =IF((DQ10-DQ11)>0,(DQ10-DQ11),0) -> 0
A13: Interest receivable | B13: =B9-B11 -> 9763888.9 | C13: =C9-C11 -> 23670833 | D13: =D9-D11 -> 7177777.7 | E13: =E9-E11 -> 21084722 | F13: =F9-F11 -> 34543055 | G13: =G9-G11 -> 7626388.9 | H13: =H9-H11 -> 21533333 | I13: =I9-I11 -> 34543056 | ... DQ13: =DQ9-DQ11 -> 0
A14: LD and others | B14: =B28 -> 0 | C14: =C28 -> 0 | D14: =D28 -> 0 | E14: =E28 -> 0 | F14: =F28 -> 0 | G14: =G28 -> 0 | H14: =H28 -> 0 | I14: =I28 -> 0 | ... DQ14: =DQ28 -> 0
B19: =B1 -> 43678 | C19: =C1 -> 43709 | D19: =D1 -> 43739 | E19: =E1 -> 43770 | F19: =F1 -> 43800 | G19: =G1 -> 43831 | H19: =H1 -> 43862 | I19: =I1 -> 43891 | ... DQ19: =DQ1 -> 47300
A20: Repayment receipts:
A21: Repayment received | B21: 0 | C21: =C4-B5 -> 0 | D21: =D4-C5 -> 0 | G21: =G4-F5 -> 0 | J21: =J4-I5 -> 0 | M21: =M4-L5 -> 0 | P21: =P4-O5 -> 0 | S21: =S4-R5 -> 0 | V21: =V4-U5 -> 50320000 | Y21: =Y4-X5 -> 50320000 | AB21: =AB4-AA5 -> 49980000 | AE21: =AE4-AD5 -> 49980000 | AH21: =AH4-AG5 -> 49980000 | AK21: =AK4-AJ5 -> 49980000 | AN21: =AN4-AM5 -> 49980000 | AQ21: =AQ4-AP5 -> 49980000 | AT21: =AT4-AS5 -> 49980000 | AW21: =AW4-AV5 -> 49980000 | AZ21: =AZ4-AY5 -> 49980000 | BC21: =BC4-BB5 -> 49980000 | BF21: =BF4-BE5 -> 49980000 | BI21: =BI4-BH5 -> 49980000 | BL21: =BL4-BK5 -> 49980000 | BO21: =BO4-BN5 -> 49980000 | BR21: =BR4-BQ5 -> 49980000 | BU21: =BU4-BT5 -> 49980000 | BX21: =BX4-BW5 -> 49980000 | CA21: =CA4-BZ5 -> 49980000 | CD21: =CD4-CC5 -> 49980000 | CG21: =CG4-CF5 -> 49980000 | CJ21: =CJ4-CI5 -> 49980000 | CM21: =CM4-CL5 -> 49980000 | CP21: =CP4-CO5 -> 49980000 | CS21: =CS4-CR5 -> 49980000 | CV21: =CV4-CU5 -> 49980000 | CY21: =CY4-CX5 -> 49980000 | DB21: =DB4-DA5 -> 49980000 | DE21: =DE4-DD5 -> 49980000 | DH21: =DH4-DG5 -> 49980000 | DK21: =DK4-DJ5 -> 49980000 | DN21: =DN4-DM5 -> 49980000 | DQ21: =DQ4-DP5 -> 49980000
A22: Repayment received (cumulative) | B22: =B21 -> 0 | C22: =B22+C21 -> 0 | D22: =C22+D21 -> 0 | E22: =D22+E21 -> 0 | F22: =E22+F21 -> 0 | G22: =F22+G21 -> 0 | H22: =G22+H21 -> 0 | I22: =H22+I21 -> 0 | J22: =I22+J21 -> 0 | ... DQ22: =DP22+DQ21 -> 1700000000
A24: Interest receipts:
A25: Interest received | B25: 0 | C25: =C10-B11 -> 0 | D25: 29951389 | G25: 40823611 | J25: 40823611 | M25: 41272222 | P25: 40493055 | S25: =S10-R11 -> 38675001 | V25: =V10-U11 -> 38250000 | Y25: =Y10-X11 -> 37942640 | AB25: =AB10-AA11 -> 36785280 | AE25: =AE10-AD11 -> 35248395 | AH25: =AH10-AG11 -> 33736500 | AK25: =AK10-AJ11 -> 33336660 | AN25: =AN10-AM11 -> 32187120 | AQ25: =AQ10-AP11 -> 30700215 | AT25: =AT10-AS11 -> 29238300 | AW25: =AW10-AV11 -> 28738500 | AZ25: =AZ10-AY11 -> 27289080 | BC25: =BC10-BB11 -> 26152035 | BF25: =BF10-BE11 -> 25014990 | BI25: =BI10-BH11 -> 23877945 | BL25: =BL10-BK11 -> 23490600 | BO25: =BO10-BN11 -> 21603855 | BR25: =BR10-BQ11 -> 19792080 | BU25: =BU10-BT11 -> 19967010 | BX25: =BX10-BW11 -> 18392640 | CA25: =CA10-BZ11 -> 17055675 | CD25: =CD10-CC11 -> 15743700 | CG25: =CG10-CF11 -> 14944020 | CJ25: =CJ10-CI11 -> 13794480 | CM25: =CM10-CL11 -> 12507495 | CP25: =CP10-CO11 -> 11245500 | CS25: =CS10-CR11 -> 10345860 | CV25: =CV10-CU11 -> 9196320 | CY25: =CY10-CX11 -> 7959315 | DB25: =DB10-DA11 -> 6822270 | DE25: =DE10-DD11 -> 5747700 | DH25: =DH10-DG11 -> 4548180 | DK25: =DK10-DJ11 -> 3411135 | DN25: =DN10-DM11 -> 2274090 | DQ25: =DQ10-DP11 -> 1137045
A26: Interest received (cumulative) | B26: =B25 -> 0 | C26: =B26+C25 -> 0 | D26: =C26+D25 -> 29951389 | E26: =D26+E25 -> 29951389 | F26: =E26+F25 -> 29951389 | G26: =F26+G25 -> 70775000 | H26: =G26+H25 -> 70775000 | I26: =H26+I25 -> 70775000 | J26: =I26+J25 -> 111598611 | ... DQ26: =DP26+DQ25 -> 9.1051552e+08
A27: LD/others | B27: 0 | C27: 0 | D27: 0 | E27: 0 | F27: 0 | G27: 0 | H27: 0 | I27: 0 | K27: 0 | L27: 0 | M27: 0 | N27: 0 | O27: 0 | P27: 0 | Q27: 0 | R27: 0 | S27: 0 | T27: 0 | U27: 0 | W27: 0 | X27: 0 | Y27: 0 | Z27: 0 | AA27: 0 | AB27: 0 | AC27: 0 | AD27: 0 | AE27: 0 | AF27: 0 | AG27: 0 | AH27: 0 | AI27: 0 | AJ27: 0 | AK27: 0 | AL27: 0 | AM27: 0 | AN27: 0 | AO27: 0 | AP27: 0 | AQ27: 0 | AR27: 0 | AS27: 0 | AT27: 0 | AU27: 0 | AV27: 0 | AW27: 0 | AX27: 0 | AY27: 0 | AZ27: 0 | BA27: 0 | BB27: 0 | BC27: 0 | BD27: 0 | BE27: 0 | BF27: 0 | BG27: 0 | BH27: 0 | BI27: 0 | BJ27: 0 | BK27: 0 | BL27: 0 | BM27: 0 | BN27: 0 | BO27: 0 | BP27: 0 | BQ27: 0 | BR27: 0 | BS27: 0 | BT27: 0 | BU27: 0 | BV27: 0 | BW27: 0 | BX27: 0 | BY27: 0 | BZ27: 0 | CA27: 0 | CB27: 0 | CC27: 0 | CD27: 0 | CE27: 0 | CF27: 0 | CG27: 0 | CH27: 0 | CI27: 0 | CJ27: 0 | CK27: 0 | CL27: 0 | CM27: 0 | CN27: 0 | CO27: 0 | CP27: 0 | CQ27: 0 | CR27: 0 | CS27: 0 | CT27: 0 | CU27: 0 | CV27: 0 | CW27: 0 | CX27: 0 | CY27: 0 | CZ27: 0 | DA27: 0 | DB27: 0 | DC27: 0 | DD27: 0 | DE27: 0 | DF27: 0 | DG27: 0 | DH27: 0 | DI27: 0 | DJ27: 0 | DK27: 0 | DL27: 0 | DM27: 0 | DN27: 0 | DO27: 0 | DP27: 0 | DQ27: 0
A28: LD/others (cumulative) | B28: =B27 -> 0 | C28: =B28+C27 -> 0 | D28: =C28+D27 -> 0 | E28: =D28+E27 -> 0 | F28: =E28+F27 -> 0 | G28: =F28+G27 -> 0 | H28: =G28+H27 -> 0 | I28: =H28+I27 -> 0 | J28: =I28+J27 -> 0 | ... DQ28: =DP28+DQ27 -> 0
A30: Actual Payment date | D30: 43720 | G30: 43816 | J30: 43905 | M30: 43997 | P30: 44088
A31: Actual Payment amount:
A32: Interest | D32: 29951389 | G32: 40823611 | J32: 40823611 | M32: 41272222 | P32: 40493055
A33: Principal
A34: LPC
A35: Total | D35: =D32+D33+D34 -> 29951389 | E35: =E32+E33+E34 -> 0 | F35: =F32+F33+F34 -> 0 | G35: =G32+G33+G34 -> 40823611 | H35: =H32+H33+H34 -> 0 | I35: =I32+I33+I34 -> 0 | J35: =J32+J33+J34 -> 40823611 | K35: =K32+K33+K34 -> 0 | ... DQ35: =DQ32+DQ33+DQ34 -> 0

Sheet SCBL_Loan
A1: Project name: | C1: =Disbursement!B1 -> Seven Circle (Bangladesh) Ltd.
A3: Agreement signing date | C3: 43626
A5: Loan Amount | C5: 1700000000 | G5: *If payment date is not a business day, then payment date shall be immediately the preceeding business day.
A7: Payment frequency | C7: Quarterly
A8: Interest Rate | C8: 0.095
A9: Maturity date | C9: 120 | D9: months | E9: =EDATE(C16,C9) -> 47301
A10: Moratorium period (Principal) | C10: 18 | D10: months | E10: =EDATE(C16,C10) -> 44198
A11: Principal | C11: As per Schedule V of TLA
A12: Interest calculation | C12: 360 | D12: days basis
A13: Number of installments | C13: 34
A15: Drawdown
C16: =Disbursement!B8 -> 43648 | D16: =Disbursement!B9 -> 43648 | E16: =Disbursement!B10 -> 43662
C17: =Disbursement!C8 -> 580000000 | D17: =Disbursement!C9 -> 120000000 | E17: =Disbursement!C10 -> 1000000000
C18: =C17 -> 580000000 | D18: =D17+C18 -> 700000000 | E18: =E17+D18 -> 1700000000
A21: Period | B21: =B28 -> 43723 | C21: =C28 -> 43814 | D21: =D28 -> 43905 | E21: =E28 -> 43997 | F21: =F28 -> 44089 | G21: =G28 -> 44180 | H21: =H28 -> 44270 | I21: =I28 -> 44362 | ... AO21: =AO28 -> 47283
A22: Quarterly Interest Rate | B22: =C8 -> 0.095 | C22: 0.095 | D22: 0.095 | E22: 0.095 | F22: 0.09 | G22: 0.09 | H22: 0.09 | I22: 0.09 | J22: 0.09 | K22: 0.09 | L22: 0.09 | M22: 0.09 | N22: 0.09 | O22: 0.09 | P22: 0.09 | Q22: 0.09 | R22: 0.09 | S22: 0.09 | T22: 0.09 | U22: 0.09 | V22: 0.09 | W22: 0.09 | X22: 0.09 | Y22: 0.09 | Z22: 0.09 | AA22: 0.09 | AB22: 0.09 | AC22: 0.09 | AD22: 0.09 | AE22: 0.09 | AF22: 0.09 | AG22: 0.09 | AH22: 0.09 | AI22: 0.09 | AJ22: 0.09 | AK22: 0.09 | AL22: 0.09 | AM22: 0.09 | AN22: 0.09 | AO22: 0.09
A24: Repayment | G24: =G28 -> 44180 | H24: =H28 -> 44270 | I24: =I28 -> 44362 | J24: =J28 -> 44454 | K24: =K28 -> 44545 | L24: =L28 -> 44635 | M24: =M28 -> 44727 | N24: =N28 -> 44819 | ... AO24: =AO28 -> 47283
H25: 0.0296 | I25: 0.0296 | J25: 0.0294 | K25: 0.0294 | L25: 0.0294 | M25: 0.0294 | N25: 0.0294 | O25: 0.0294 | P25: 0.0294 | Q25: 0.0294 | R25: 0.0294 | S25: 0.0294 | T25: 0.0294 | U25: 0.0294 | V25: 0.0294 | W25: 0.0294 | X25: 0.0294 | Y25: 0.0294 | Z25: 0.0294 | AA25: 0.0294 | AB25: 0.0294 | AC25: 0.0294 | AD25: 0.0294 | AE25: 0.0294 | AF25: 0.0294 | AG25: 0.0294 | AH25: 0.0294 | AI25: 0.0294 | AJ25: 0.0294 | AK25: 0.0294 | AL25: 0.0294 | AM25: 0.0294 | AN25: 0.0294 | AO25: 0.0294
A26: Cumulative | F26: 44056
A27: Repayment Period | H27: =G27+1 -> 1 | I27: =H27+1 -> 2 | J27: =I27+1 -> 3 | K27: =J27+1 -> 4 | L27: =K27+1 -> 5 | M27: =L27+1 -> 6 | N27: =M27+1 -> 7 | O27: =N27+1 -> 8 | ... AO27: =AN27+1 -> 34
A28: Repayment Date | B28: 43723 | C28: 43814 | D28: 43905 | E28: 43997 | F28: 44089 | G28: 44180 | H28: 44270 | I28: 44362 | J28: 44454 | K28: 44545 | L28: 44635 | M28: 44727 | N28: 44819 | O28: 44910 | P28: 45000 | Q28: 45092 | R28: 45183 | S28: 45274 | T28: 45365 | U28: 45456 | V28: 45550 | W28: 45641 | X28: 45729 | Y28: 45823 | Z28: 45915 | AA28: 46006 | AB28: 46096 | AC28: 46188 | AD28: 46280 | AE28: 46371 | AF28: 46461 | AG28: 46553 | AH28: 46645 | AI28: 46736 | AJ28: 46827 | AK28: 46919 | AL28: 47010 | AM28: 47101 | AN28: 47192 | AO28: 47283
A29: Opening Balance | B29: =B42+B55+B68 -> 1700000000 | C29: =C42+C55+C68 -> 1700000000 | D29: =D42+D55+D68 -> 1700000000 | E29: =E42+E55+E68 -> 1700000000 | F29: =F42+F55+F68 -> 1700000000 | G29: =G42+G55+G68 -> 1700000000 | H29: =H42+H55+H68 -> 1700000000 | I29: =I42+I55+I68 -> 1649680000 | ... AO29: =AO42+AO55+AO68 -> 49980000
A30: Interest Payment | B30: =B43+B56+B69 -> 29951389 | C30: =C43+C56+C69 -> 40823611 | D30: =D43+D56+D69 -> 40823611 | E30: =E43+E56+E69 -> 41272222 | F30: =F43+F56+F69 -> 40493056 | G30: =G43+G56+G69 -> 38675000 | H30: =H43+H56+H69 -> 38250000 | I30: =I43+I56+I69 -> 37942640 | ... AO30: =AO43+AO56+AO69 -> 1137045
A31: Cumulative interest | B31: =B30 -> 29951389 | C31: =B31+C30 -> 70775000 | D31: =C31+D30 -> 1.1159861e+08 | E31: =D31+E30 -> 1.5287083e+08 | F31: =E31+F30 -> 1.9336389e+08 | G31: =G30+F31 -> 2.3203889e+08 | H31: =H30+G31 -> 2.7028889e+08 | I31: =I30+H31 -> 3.0823153e+08 | J31: =J30+I31 -> 3.4501681e+08 | K31: =K30+J31 -> 3.802652e+08 | L31: =L30+K31 -> 4.140017e+08 | M31: =M30+L31 -> 4.4733836e+08 | N31: =N30+M31 -> 4.7952548e+08 | ... AO31: =AO30+AN31 -> 9.1051552e+08
A32: Principal Payment | B32: =B45+B58+B71 -> 0 | C32: =C45+C58+C71 -> 0 | D32: =D45+D58+D71 -> 0 | E32: =E45+E58+E71 -> 0 | F32: =F45+F58+F71 -> 0 | G32: =G45+G58+G71 -> 0 | H32: =H45+H58+H71 -> 50320000 | I32: =I45+I58+I71 -> 50320000 | ... AO32: =AO45+AO58+AO71 -> 49980000
A33: Cumulative repayment | B33: 0 | C33: =C32+B33 -> 0 | D33: =D32+C33 -> 0 | E33: =E32+D33 -> 0 | F33: =F32+E33 -> 0 | G33: =G32+F33 -> 0 | H33: =H32+G33 -> 50320000 | I33: =I32+H33 -> 100640000 | J33: =J32+I33 -> 150620000 | ... AO33: =AO32+AN33 -> 1700000000
A34: Total Debt Service | B34: =B30+B32 -> 29951389 | C34: =C30+C32 -> 40823611 | D34: =D30+D32 -> 40823611 | E34: =E30+E32 -> 41272222 | F34: =F30+F32 -> 40493056 | G34: =G30+G32 -> 38675000 | H34: =H30+H32 -> 88570000 | I34: =I30+I32 -> 88262640 | ... AO34: =AO30+AO32 -> 51117045
A35: Closing Balance | B35: =B29-B32 -> 1700000000 | C35: =C29-C32 -> 1700000000 | D35: =D29-D32 -> 1700000000 | E35: =E29-E32 -> 1700000000 | F35: =F29-F32 -> 1700000000 | G35: =G29-G32 -> 1700000000 | H35: =H29-H32 -> 1649680000 | I35: =I29-I32 -> 1599360000 | ... AO35: =AO29-AO32 -> 0
A37: Disbursement-1 (part-1)
A38: Period | B38: =B21 -> 43723 | C38: =C21 -> 43814 | D38: =D21 -> 43905 | E38: =E21 -> 43997 | F38: =F21 -> 44089 | G38: =G21 -> 44180 | H38: =H21 -> 44270 | I38: =I21 -> 44362 | ... AO38: =AO21 -> 47283
A39: Expected Interest Rate | B39: =B22 -> 0.095 | C39: =C22 -> 0.095 | D39: =D22 -> 0.095 | E39: =E22 -> 0.095 | F39: =F22 -> 0.09 | G39: =G22 -> 0.09 | H39: =H22 -> 0.09 | I39: =I22 -> 0.09 | ... AO39: =AO22 -> 0.09
A40: Repayment Period | G40: =G27 -> 0 | H40: =H27 -> 1 | I40: =I27 -> 2 | J40: =J27 -> 3 | K40: =K27 -> 4 | L40: =L27 -> 5 | M40: =M27 -> 6 | N40: =N27 -> 7 | ... AO40: =AO27 -> 34
A41: Repayment Date | B41: =B28 -> 43723 | C41: =C28 -> 43814 | D41: =D28 -> 43905 | E41: =E28 -> 43997 | F41: =F28 -> 44089 | G41: =G28 -> 44180 | H41: =H28 -> 44270 | I41: =I28 -> 44362 | ... AO41: =AO28 -> 47283
A42: Opening Balance | B42: =C17 -> 580000000 | C42: =B48 -> 580000000 | D42: =C48 -> 580000000 | E42: =D48 -> 580000000 | F42: =E48 -> 580000000 | G42: =F48 -> 580000000 | H42: =G48 -> 580000000 | I42: =H48 -> 562832000 | J42: =I48 -> 545664000 | ... AO42: =AN48 -> 17052000
A43: Interest Payment | B43: =C18*(B41-C16)*$B$39/360 -> 11479167 | C43: =B48*(C41-B41)*C39/360 -> 13928056 | D43: =C48*(D41-C41)*D39/360 -> 13928056 | E43: =D48*(E41-D41)*E39/360 -> 14081111 | F43: =E48*($F$26-E41)*E39/360+E48*(F41-$F$26)*F39/360 -> 13815278 | G43: =F48*(G41-F41)*G39/360 -> 13195000 | H43: =G48*(H41-G41)*H39/360 -> 13050000 | I43: =H48*(I41-H41)*I39/360 -> 12945136 | J43: =I48*(J41-I41)*J39/360 -> 12550272 | K43: =J48*(K41-J41)*K39/360 -> 12025923 | L43: =K48*(L41-K41)*L39/360 -> 11510100 | M43: =L48*(M41-L41)*M39/360 -> 11373684 | N43: =M48*(N41-M41)*N39/360 -> 10981488 | ... AO43: =AN48*(AO41-AN41)*AO39/360 -> 387933
A44: Cumulative interest | B44: =B43 -> 11479167 | C44: =B44+C43 -> 25407222 | D44: =C44+D43 -> 39335278 | E44: =D44+E43 -> 53416389 | F44: =E44+F43 -> 67231667 | G44: =G43+F44 -> 80426667 | H44: =H43+G44 -> 93476667 | I44: =I43+H44 -> 1.064218e+08 | J44: =J43+I44 -> 1.1897207e+08 | K44: =K43+J44 -> 1.30998e+08 | L44: =L43+K44 -> 1.425081e+08 | M44: =M43+L44 -> 1.5388178e+08 | N44: =N43+M44 -> 1.6486327e+08 | ... AO44: =AO43+AN44 -> 3.1190693e+08
A45: Principal Payment | B45: 0 | C45: 0 | D45: 0 | E45: 0 | F45: 0 | G45: 0 | H45: =$C$18*H25 -> 17168000 | I45: =$C$18*I25 -> 17168000 | J45: =$C$18*J25 -> 17052000 | K45: =$C$18*K25 -> 17052000 | L45: =$C$18*L25 -> 17052000 | M45: =$C$18*M25 -> 17052000 | N45: =$C$18*N25 -> 17052000 | O45: =$C$18*O25 -> 17052000 | ... AO45: =$C$18*AO25 -> 17052000
A46: Cumulative repayment | B46: 0 | C46: =C45+B46 -> 0 | D46: =D45+C46 -> 0 | E46: =E45+D46 -> 0 | F46: =F45+E46 -> 0 | G46: =G45+F46 -> 0 | H46: =H45+G46 -> 17168000 | I46: =I45+H46 -> 34336000 | J46: =J45+I46 -> 51388000 | ... AO46: =AO45+AN46 -> 580000000
A47: Total Debt Service | B47: =B43+B45 -> 11479167 | C47: =C43+C45 -> 13928056 | D47: =D43+D45 -> 13928056 | E47: =E43+E45 -> 14081111 | F47: =F43+F45 -> 13815278 | G47: =G43+G45 -> 13195000 | H47: =H43+H45 -> 30218000 | I47: =I43+I45 -> 30113136 | ... AO47: =AO43+AO45 -> 17439933
A48: Closing Balance | B48: =B42-B45 -> 580000000 | C48: =C42-C45 -> 580000000 | D48: =D42-D45 -> 580000000 | E48: =E42-E45 -> 580000000 | F48: =F42-F45 -> 580000000 | G48: =G42-G45 -> 580000000 | H48: =H42-H45 -> 562832000 | I48: =I42-I45 -> 545664000 | ... AO48: =AO42-AO45 -> 0
...

Sheet Accrual_SCBL 
A1: Project name: | B1: =SCBL_Loan!C1 -> Seven Circle (Bangladesh) Ltd.
A3: Assumptions:
A5: Agreement signing date | B5: =SCBL_Loan!C3 -> 43626
A7: Loan Amount | B7: =SCBL_Loan!C5 -> 1700000000 | C7: BDT
A9: Interest Rate | B9: =SCBL_Loan!C8 -> 0.095
A10: Tenor | B10: 10 years
A11: Interest calculation | B11: 360 | C11: days basis
A12: Principal | B12: =SCBL_Loan!C11 -> As per Schedule V of TLA
A14: Drawdown
C15: =SCBL_Loan!C16 -> 43648 | D15: =SCBL_Loan!D16 -> 43648 | E15: =SCBL_Loan!E16 -> 43662
C16: =SCBL_Loan!C17 -> 580000000 | D16: =SCBL_Loan!D17 -> 120000000 | E16: =SCBL_Loan!E17 -> 1000000000
C17: =C16 -> 580000000 | D17: =D16+C17 -> 700000000 | E17: =E16+D17 -> 1700000000
A22: Cumulative Accrual
A23: Months | B23: 43678 | C23: =EDATE(B23,1) -> 43709 | D23: =EDATE(C23,1) -> 43739 | E23: =EDATE(D23,1) -> 43770 | F23: =EDATE(E23,1) -> 43800 | G23: =EDATE(F23,1) -> 43831 | H23: =EDATE(G23,1) -> 43862 | I23: =EDATE(H23,1) -> 43891 | J23: =EDATE(I23,1) -> 43922 | ... DQ23: =EDATE(DP23,1) -> 47300
A24: Opening Balance | B24: =B36+B48+B60 -> 1700000000 | C24: =C36+C48+C60 -> 1700000000 | D24: =D36+D48+D60 -> 1700000000 | E24: =E36+E48+E60 -> 1700000000 | F24: =F36+F48+F60 -> 1700000000 | G24: =G36+G48+G60 -> 1700000000 | H24: =H36+H48+H60 -> 1700000000 | I24: =I36+I48+I60 -> 1700000000 | ... DQ24: =DQ36+DQ48+DQ60 -> 49980000
A25: Interest Payment | B25: =B37+B49+B61 -> 9763888.9 | C25: =C37+C49+C61 -> 13906944 | D25: =D37+D49+D61 -> 13458333 | E25: =E37+E49+E61 -> 13906944 | F25: =F37+F49+F61 -> 13458333 | G25: =G37+G49+G61 -> 13906944 | H25: =H37+H49+H61 -> 13906944 | I25: =I37+I49+I61 -> 13009722 | ... DQ25: =DQ37+DQ49+DQ61 -> 162435
A26: Cumulative interest | B26: =B38+B50+B62 -> 9763888.9 | C26: =C38+C50+C62 -> 23670833 | D26: =D38+D50+D62 -> 37129167 | E26: =E38+E50+E62 -> 51036111 | F26: =F38+F50+F62 -> 64494444 | G26: =G38+G50+G62 -> 78401389 | H26: =H38+H50+H62 -> 92308333 | I26: =I38+I50+I62 -> 1.0531806e+08 | ... DQ26: =DQ38+DQ50+DQ62 -> 9.1051552e+08
A27: Principal Payment | B27: =B39+B51+B63 -> 0 | C27: =C39+C51+C63 -> 0 | D27: =D39+D51+D63 -> 0 | E27: =E39+E51+E63 -> 0 | F27: =F39+F51+F63 -> 0 | G27: =G39+G51+G63 -> 0 | H27: =H39+H51+H63 -> 0 | I27: =I39+I51+I63 -> 0 | ... DQ27: =DQ39+DQ51+DQ63 -> 49980000
A28: Cumulative repayment | B28: =B27 -> 0 | C28: =B28+C27 -> 0 | D28: =C28+D27 -> 0 | E28: =D28+E27 -> 0 | F28: =E28+F27 -> 0 | G28: =F28+G27 -> 0 | H28: =G28+H27 -> 0 | I28: =H28+I27 -> 0 | J28: =I28+J27 -> 0 | ... DQ28: =DP28+DQ27 -> 1700000000
A29: Total Debt Service | B29: =B27+B25 -> 9763888.9 | C29: =C27+C25 -> 13906944 | D29: =D27+D25 -> 13458333 | E29: =E27+E25 -> 13906944 | F29: =F27+F25 -> 13458333 | G29: =G27+G25 -> 13906944 | H29: =H27+H25 -> 13906944 | I29: =I27+I25 -> 13009722 | ... DQ29: =DQ27+DQ25 -> 50142435
A30: Closing Balance | B30: =B24-B27 -> 1700000000 | C30: =C24-C27 -> 1700000000 | D30: =D24-D27 -> 1700000000 | E30: =E24-E27 -> 1700000000 | F30: =F24-F27 -> 1700000000 | G30: =G24-G27 -> 1700000000 | H30: =H24-H27 -> 1700000000 | I30: =I24-I27 -> 1700000000 | ... DQ30: =DQ24-DQ27 -> 0
DQ31: =DQ26-SCBL_Loan!AO31 -> 0
A32: Disbursement-1 (a) | O32: =+SCBL_Loan!F26 -> 44056
A33: Period
A34: Expected Interest Rate | B34: =B9 -> 0.095 | C34: 0.095 | D34: 0.095 | E34: 0.095 | F34: 0.095 | G34: 0.095 | H34: 0.095 | I34: 0.095 | J34: 0.095 | K34: 0.095 | L34: 0.095 | M34: 0.095 | N34: 0.095 | O34: 0.09 | P34: 0.09 | Q34: 0.09 | R34: 0.09 | S34: 0.09 | T34: 0.09 | U34: 0.09 | V34: 0.09 | W34: 0.09 | X34: 0.09 | Y34: 0.09 | Z34: 0.09 | AA34: 0.09 | AB34: 0.09 | AC34: 0.09 | AD34: 0.09 | AE34: 0.09 | AF34: 0.09 | AG34: 0.09 | AH34: 0.09 | AI34: 0.09 | AJ34: 0.09 | AK34: 0.09 | AL34: 0.09 | AM34: 0.09 | AN34: 0.09 | AO34: 0.09 | AP34: 0.09 | AQ34: 0.09 | AR34: 0.09 | AS34: 0.09 | AT34: 0.09 | AU34: 0.09 | AV34: 0.09 | AW34: 0.09 | AX34: 0.09 | AY34: 0.09 | AZ34: 0.09 | BA34: 0.09 | BB34: 0.09 | BC34: 0.09 | BD34: 0.09 | BE34: 0.09 | BF34: 0.09 | BG34: 0.09 | BH34: 0.09 | BI34: 0.09 | BJ34: 0.09 | BK34: 0.09 | BL34: 0.09 | BM34: 0.09 | BN34: 0.09 | BO34: 0.09 | BP34: 0.09 | BQ34: 0.09 | BR34: 0.09 | BS34: 0.09 | BT34: 0.09 | BU34: 0.09 | BV34: 0.09 | BW34: 0.09 | BX34: 0.09 | BY34: 0.09 | BZ34: 0.09 | CA34: 0.09 | CB34: 0.09 | CC34: 0.09 | CD34: 0.09 | CE34: 0.09 | CF34: 0.09 | CG34: 0.09 | CH34: 0.09 | CI34: 0.09 | CJ34: 0.09 | CK34: 0.09 | CL34: 0.09 | CM34: 0.09 | CN34: 0.09 | CO34: 0.09 | CP34: 0.09 | CQ34: 0.09 | CR34: 0.09 | CS34: 0.09 | CT34: 0.09 | CU34: 0.09 | CV34: 0.09 | CW34: 0.09 | CX34: 0.09 | CY34: 0.09 | CZ34: 0.09 | DA34: 0.09 | DB34: 0.09 | DC34: 0.09 | DD34: 0.09 | DE34: 0.09 | DF34: 0.09 | DG34: 0.09 | DH34: 0.09 | DI34: 0.09 | DJ34: 0.09 | DK34: 0.09 | DL34: 0.09 | DM34: 0.09 | DN34: 0.09 | DO34: 0.09 | DP34: 0.09 | DQ34: 0.09
A35: Months | B35: 43678 | C35: =EDATE(B35,1) -> 43709 | D35: =EDATE(C35,1) -> 43739 | E35: =EDATE(D35,1) -> 43770 | F35: =EDATE(E35,1) -> 43800 | G35: =EDATE(F35,1) -> 43831 | H35: =EDATE(G35,1) -> 43862 | I35: =EDATE(H35,1) -> 43891 | J35: =EDATE(I35,1) -> 43922 | ... DQ35: =EDATE(DP35,1) -> 47300
A36: Opening Balance | B36: =C16 -> 580000000 | C36: =B42 -> 580000000 | D36: =C42 -> 580000000 | E36: =D42 -> 580000000 | F36: =E42 -> 580000000 | G36: =F42 -> 580000000 | H36: =G42 -> 580000000 | I36: =H42 -> 580000000 | J36: =I42 -> 580000000 | ... DQ36: =DP42 -> 17052000
A37: Interest Payment | B37: =B36*(B35-C15)*B34/360 -> 4591666.7 | C37: =C36*(C35-B35)*C34/360 -> 4744722.2 | D37: =D36*(D35-C35)*D34/360 -> 4591666.7 | E37: =E36*(E35-D35)*E34/360 -> 4744722.2 | F37: =F36*(F35-E35)*F34/360 -> 4591666.7 | G37: =G36*(SCBL_Loan!$C$28-F35)*F34/360+G42*(G35-SCBL_Loan!$C$28)*G34/360 -> 4744722.2 | H37: =H36*(H35-G35)*H34/360 -> 4744722.2 | I37: =I36*(I35-H35)*I34/360 -> 4438611.1 | J37: =J36*(J35-I35)*J34/360 -> 4744722.2 | K37: =K36*(K35-J35)*K34/360 -> 4591666.7 | L37: =L36*(L35-K35)*L34/360 -> 4744722.2 | M37: =M36*(M35-L35)*M34/360 -> 4591666.7 | N37: =N36*(N35-M35)*N34/360 -> 4744722.2 | O37: =O36*($O$32-N35)*N34/360+O36*(O35-$O$32)*O34/360 -> 4591666.7 | P37: =P36*(P35-O35)*P34/360 -> 4350000 | Q37: =Q36*(Q35-P35)*Q34/360 -> 4495000 | R37: =R36*(R35-Q35)*R34/360 -> 4350000 | S37: =S36*(SCBL_Loan!$G$28-R35)*R34/360+S42*(S35-SCBL_Loan!$G$28)*S34/360 -> 4495000 | T37: =T36*(T35-S35)*T34/360 -> 4495000 | U37: =U36*(U35-T35)*U34/360 -> 4060000 | V37: =V36*(SCBL_Loan!$H$28-U35)*U34/360+V42*(V35-SCBL_Loan!$H$28)*V34/360 -> 4422036 | W37: =W36*(W35-V35)*W34/360 -> 4221240 | X37: =X36*(X35-W35)*X34/360 -> 4361948 | Y37: =Y36*(SCBL_Loan!$I$28-X35)*X34/360+Y42*(Y35-SCBL_Loan!$I$28)*Y34/360 -> 4152568 | Z37: =Z36*(Z35-Y35)*Z34/360 -> 4228896 | AA37: =AA36*(AA35-Z35)*AA34/360 -> 4228896 | AB37: =AB36*(SCBL_Loan!$J$28-AA35)*AA34/360+AB42*(AB35-SCBL_Loan!$J$28)*AB34/360 -> 4024272 | AC37: =AC36*(AC35-AB35)*AC34/360 -> 4096743 | AD37: =AD36*(AD35-AC35)*AD34/360 -> 3964590 | AE37: =AE36*(SCBL_Loan!$K$28-AD35)*AD34/360+AE42*(AE35-SCBL_Loan!$K28)*AE34/360 -> 4024272 | AF37: =AF36*(AF35-AE35)*AF34/360 -> 3964590 | AG37: =AG36*(AG35-AF35)*AG34/360 -> 3580920 | AH37: =AH36*(SCBL_Loan!$L$28-AG35)*AG34/360+AH42*(AH35-SCBL_Loan!$L$28)*AH34/360 -> 3892119 | AI37: =AI36*(AI35-AH35)*AI34/360 -> 3708810 | AJ37: =AJ36*(AJ35-AI35)*AJ34/360 -> 3832437 | AK37: =AK36*(SCBL_Loan!$M$28-AJ35)*AJ34/360+AK42*(AK35-SCBL_Loan!$M$28)*AK34/360 -> 3640602 | AL37: =AL36*(AL35-AK35)*AL34/360 -> 3700284 | AM37: =AM36*(AM35-AL35)*AM34/360 -> 3700284 | AN37: =AN36*(SCBL_Loan!$N$28-AM35)*AM34/360+AN42*(AN35-SCBL_Loan!$N$28)*AN34/360 -> 3512712 | AO37: =AO36*(AO35-AN35)*AO34/360 -> 3568131 | AP37: =AP36*(AP35-AO35)*AP34/360 -> 3453030 | AQ37: =AQ36*(SCBL_Loan!$O$28-AP35)*AP34/360+AQ42*(AQ35-SCBL_Loan!$O$28)*AQ34/360 -> 3495660 | AR37: =AR36*(AR35-AQ35)*AR34/360 -> 3435978 | AS37: =AS36*(AS35-AR35)*AS34/360 -> 3103464 | AT37: =AT36*(SCBL_Loan!$P$28-AS35)*AS34/360+AT42*(AT35-SCBL_Loan!$P$28)*AT34/360 -> 3363507 | AU37: =AU36*(AU35-AT35)*AU34/360 -> 3197250 | AV37: =AV36*(AV35-AU35)*AV34/360 -> 3303825 | AW37: =AW36*(SCBL_Loan!$Q$28-AV35)*AV34/360+AW42*(AW35-SCBL_Loan!$Q$28)*AW34/360 -> 3129042 | AX37: =AX36*(AX35-AW35)*AX34/360 -> 3171672 | AY37: =AY36*(AY35-AX35)*AY34/360 -> 3171672 | AZ37: =AZ36*(SCBL_Loan!$R$28-AY35)*AY34/360+AZ42*(AZ35-SCBL_Loan!$R$28)*AZ34/360 -> 2996889 | BA37: =BA36*(BA35-AZ35)*BA34/360 -> 3039519 | BB37: =BB36*(BB35-BA35)*BB34/360 -> 2941470 | BC37: =BC36*(SCBL_Loan!$S$28-BB35)*BB34/360+BC42*(BC35-SCBL_Loan!$S$28)*BC34/360 -> 2962785 | BD37: =BD36*(BD35-BC35)*BD34/360 -> 2907366 | BE37: =BE36*(BE35-BD35)*BE34/360 -> 2719794 | BF37: =BF36*(SCBL_Loan!$T$28-BE35)*BE34/360+BF42*(BF35-SCBL_Loan!$T$28)*BF34/360 -> 2830632 | BG37: =BG36*(BG35-BF35)*BG34/360 -> 2685690 | BH37: =BH36*(BH35-BG35)*BH34/360 -> 2775213 | BI37: =BI36*(SCBL_Loan!$U$28-BH35)*BH34/360+BI42*(BI35-SCBL_Loan!$U$28)*BI34/360 -> 2608956 | BJ37: =BJ36*(BJ35-BI35)*BJ34/360 -> 2643060 | BK37: =BK36*(BK35-BJ35)*BK34/360 -> 2643060 | BL37: =BL36*(SCBL_Loan!$V$28-BK35)*BK34/360+BL42*(BL35-SCBL_Loan!$V$28)*BL34/360 -> 2489592 | BM37: =BM36*(BM35-BL35)*BM34/360 -> 2510907 | BN37: =BN36*(BN35-BM35)*BN34/360 -> 2429910 | BO37: =BO36*(SCBL_Loan!$W$28-BN35)*BN34/360+BO42*(BO35-SCBL_Loan!$W$28)*BO34/360 -> 2438436 | BP37: =BP36*(BP35-BO35)*BP34/360 -> 2378754 | BQ37: =BQ36*(BQ35-BP35)*BQ34/360 -> 2148552 | BR37: =BR36*(SCBL_Loan!$X$28-BQ35)*BQ34/360+BR42*(BR35-SCBL_Loan!$X$28)*BR34/360 -> 2297757 | BS37: =BS36*(BS35-BR35)*BS34/360 -> 2174130 | BT37: =BT36*(BT35-BS35)*BT34/360 -> 2246601 | BU37: =BU36*(SCBL_Loan!$Y$28-BT35)*BT34/360+BU42*(BU35-SCBL_Loan!$Y$28)*BU34/360 -> 2105922 | BV37: =BV36*(BV35-BU35)*BV34/360 -> 2114448 | BW37: =BW36*(BW35-BV35)*BW34/360 -> 2114448 | BX37: =BX36*(SCBL_Loan!$Z$28-BW35)*BW34/360+BX42*(BX35-SCBL_Loan!$Z$28)*BX34/360 -> 1978032 | BY37: =BY36*(BY35-BX35)*BY34/360 -> 1982295 | BZ37: =BZ36*(BZ35-BY35)*BZ34/360 -> 1918350 | CA37: =CA36*(SCBL_Loan!$AA$28-BZ35)*BZ34/360+CA42*(CA35-SCBL_Loan!$AA$28)*CA34/360 -> 1909824 | CB37: =CB36*(CB35-CA35)*CB34/360 -> 1850142 | CC37: =CC36*(CC35-CB35)*CC34/360 -> 1671096 | CD37: =CD36*(SCBL_Loan!$AB$28-CC35)*CC34/360+CD42*(CD35-SCBL_Loan!$AB$28)*CD34/360 -> 1777671 | CE37: =CE36*(CE35-CD35)*CE34/360 -> 1662570 | CF37: =CF36*(CF35-CE35)*CF34/360 -> 1717989 | CG37: =CG36*(SCBL_Loan!$AC$28-CF35)*CF34/360+CG42*(CG35-SCBL_Loan!$AC$28)*CG34/360 -> 1594362 | CH37: =CH36*(CH35-CG35)*CH34/360 -> 1585836 | CI37: =CI36*(CI35-CH35)*CI34/360 -> 1585836 | CJ37: =CJ36*(SCBL_Loan!$AD$28-CI35)*CI34/360+CJ42*(CJ35-SCBL_Loan!$AD$28)*CJ34/360 -> 1466472 | CK37: =CK36*(CK35-CJ35)*CK34/360 -> 1453683 | CL37: =CL36*(CL35-CK35)*CL34/360 -> 1406790 | CM37: =CM36*(SCBL_Loan!$AE$28-CL35)*CL34/360+CM42*(CM35-SCBL_Loan!$AE$28)*CM34/360 -> 1381212 | CN37: =CN36*(CN35-CM35)*CN34/360 -> 1321530 | CO37: =CO36*(CO35-CN35)*CO34/360 -> 1193640 | CP37: =CP36*(SCBL_Loan!$AF$28-CO35)*CO34/360+CP42*(CP35-SCBL_Loan!$AF$28)*CP34/360 -> 1249059 | CQ37: =CQ36*(CQ35-CP35)*CQ34/360 -> 1151010 | CR37: =CR36*(CR35-CQ35)*CR34/360 -> 1189377 | CS37: =CS36*(SCBL_Loan!$AG$28-CR35)*CR34/360+CS42*(CS35-SCBL_Loan!$AG$28)*CS34/360 -> 1082802 | CT37: =CT36*(CT35-CS35)*CT34/360 -> 1057224 | CU37: =CU36*(CU35-CT35)*CU34/360 -> 1057224 | CV37: =CV36*(SCBL_Loan!$AH$28-CU35)*CU34/360+CV42*(CV35-SCBL_Loan!$AH$28)*CV34/360 -> 954912 | CW37: =CW36*(CW35-CV35)*CW34/360 -> 925071 | CX37: =CX36*(CX35-CW35)*CX34/360 -> 895230 | CY37: =CY36*(SCBL_Loan!$AI$28-CX35)*CX34/360+CY42*(CY35-SCBL_Loan!$AI$28)*CY34/360 -> 852600 | CZ37: =CZ36*(CZ35-CY35)*CZ34/360 -> 792918 | DA37: =DA36*(DA35-CZ35)*DA34/360 -> 741762 | DB37: =DB36*(SCBL_Loan!$AJ$28-DA35)*DA34/360+DB42*(DB35-SCBL_Loan!$AJ$28)*DB34/360 -> 720447 | DC37: =DC36*(DC35-DB35)*DC34/360 -> 639450 | DD37: =DD36*(DD35-DC35)*DD34/360 -> 660765 | DE37: =DE36*(SCBL_Loan!$AK$28-DD35)*DD34/360+DE42*(DE35-SCBL_Loan!$AK$28)*DE34/360 -> 571242 | DF37: =DF36*(DF35-DE35)*DF34/360 -> 528612 | DG37: =DG36*(DG35-DF35)*DG34/360 -> 528612 | DH37: =DH36*(SCBL_Loan!$AL$28-DG35)*DG34/360+DH42*(DH35-SCBL_Loan!$AL$28)*DH34/360 -> 439089 | DI37: =DI36*(DI35-DH35)*DI34/360 -> 396459 | DJ37: =DJ36*(DJ35-DI35)*DJ34/360 -> 383670 | DK37: =DK36*(SCBL_Loan!$AM$28-DJ35)*DJ34/360+DK42*(DK35-SCBL_Loan!$AM$28)*DK34/360 -> 319725 | DL37: =DL36*(DL35-DK35)*DL34/360 -> 264306 | DM37: =DM36*(DM35-DL35)*DM34/360 -> 238728 | DN37: =DN36*(SCBL_Loan!$AN$28-DM35)*DM34/360+DN42*(DN35-SCBL_Loan!$AN$28)*DN34/360 -> 191835 | DO37: =DO36*(DO35-DN35)*DO34/360 -> 127890 | DP37: =DP36*(DP35-DO35)*DP34/360 -> 132153 | DQ37: =DQ36*(SCBL_Loan!$AO$28-DP35)*DP34/360+DQ42*(DQ35-SCBL_Loan!$AO$28)*DQ34/360 -> 55419
A38: Cumulative interest | B38: =B37 -> 4591666.7 | C38: =B38+C37 -> 9336388.9 | D38: =C38+D37 -> 13928056 | E38: =D38+E37 -> 18672778 | F38: =E38+F37 -> 23264444 | G38: =F38+G37 -> 28009167 | H38: =G38+H37 -> 32753889 | I38: =H38+I37 -> 37192500 | J38: =I38+J37 -> 41937222 | ... DQ38: =DP38+DQ37 -> 3.1190693e+08
A39: Principal Payment | B39: 0 | C39: =B39 -> 0 | D39: =C39 -> 0 | E39: =D39 -> 0 | F39: =E39 -> 0 | G39: =F39 -> 0 | H39: =G39 -> 0 | I39: =H39 -> 0 | J39: =I39 -> 0 | ... R39: =Q39 -> 0 | S39: =SCBL_Loan!$G$45 -> 0 | T39: 0 | U39: 0 | V39: =SCBL_Loan!$H$45 -> 17168000 | W39: 0 | X39: 0 | Y39: =SCBL_Loan!$I$45 -> 17168000 | Z39: 0 | AA39: 0 | AB39: =SCBL_Loan!$J$45 -> 17052000 | AC39: 0 | AD39: 0 | AE39: =SCBL_Loan!$K$45 -> 17052000 | AF39: 0 | AG39: 0 | AH39: =SCBL_Loan!$L$45 -> 17052000 | AI39: 0 | AJ39: 0 | AK39: =SCBL_Loan!$M$45 -> 17052000 | AL39: 0 | AM39: 0 | AN39: =SCBL_Loan!$N$45 -> 17052000 | AO39: 0 | AP39: 0 | AQ39: =SCBL_Loan!$O$45 -> 17052000 | AR39: 0 | AS39: 0 | AT39: =SCBL_Loan!$P$45 -> 17052000 | AU39: 0 | AV39: 0 | AW39: =SCBL_Loan!$Q$45 -> 17052000 | AX39: 0 | AY39: 0 | AZ39: =SCBL_Loan!$R$45 -> 17052000 | BA39: 0 | BB39: 0 | BC39: =SCBL_Loan!$S$45 -> 17052000 | BD39: 0 | BE39: 0 | BF39: =SCBL_Loan!$T$45 -> 17052000 | BG39: 0 | BH39: 0 | BI39: =SCBL_Loan!$U$45 -> 17052000 | BJ39: 0 | BK39: 0 | BL39: =SCBL_Loan!$V$45 -> 17052000 | BM39: 0 | BN39: 0 | BO39: =SCBL_Loan!$W$45 -> 17052000 | BP39: 0 | BQ39: 0 | BR39: =SCBL_Loan!$X$45 -> 17052000 | BS39: 0 | BT39: 0 | BU39: =SCBL_Loan!$Y$45 -> 17052000 | BV39: 0 | BW39: 0 | BX39: =SCBL_Loan!$Z$45 -> 17052000 | BY39: 0 | BZ39: 0 | CA39: =SCBL_Loan!$AA$45 -> 17052000 | CB39: 0 | CC39: 0 | CD39: =SCBL_Loan!$AB$45 -> 17052000 | CE39: 0 | CF39: 0 | CG39: =SCBL_Loan!$AC$45 -> 17052000 | CH39: 0 | CI39: 0 | CJ39: =SCBL_Loan!$AD$45 -> 17052000 | CK39: 0 | CL39: 0 | CM39: =SCBL_Loan!$AE$45 -> 17052000 | CN39: 0 | CO39: 0 | CP39: =SCBL_Loan!$AF$45 -> 17052000 | CQ39: 0 | CR39: 0 | CS39: =SCBL_Loan!$AG$45 -> 17052000 | CT39: 0 | CU39: 0 | CV39: =SCBL_Loan!$AH$45 -> 17052000 | CW39: 0 | CX39: 0 | CY39: =SCBL_Loan!$AI$45 -> 17052000 | CZ39: 0 | DA39: 0 | DB39: =SCBL_Loan!$AJ$45 -> 17052000 | DC39: 0 | DD39: 0 | DE39: =SCBL_Loan!$AK$45 -> 17052000 | DF39: 0 | DG39: 0 | DH39: =SCBL_Loan!$AL$45 -> 17052000 | DI39: 0 | DJ39: 0 | DK39: =SCBL_Loan!$AM$45 -> 17052000 | DL39: 0 | DM39: 0 | DN39: =SCBL_Loan!$AN$45 -> 17052000 | DO39: 0 | DP39: 0 | DQ39: =SCBL_Loan!$AN$45 -> 17052000
A40: Cumulative repayment | B40: =B39 -> 0 | C40: =B40+C39 -> 0 | D40: =C40+D39 -> 0 | E40: =D40+E39 -> 0 | F40: =E40+F39 -> 0 | G40: =F40+G39 -> 0 | H40: =G40+H39 -> 0 | I40: =H40+I39 -> 0 | J40: =I40+J39 -> 0 | ... DQ40: =DP40+DQ39 -> 580000000
A41: Total Debt Service | B41: =B39+B37 -> 4591666.7 | C41: =C39+C37 -> 4744722.2 | D41: =D39+D37 -> 4591666.7 | E41: =E39+E37 -> 4744722.2 | F41: =F39+F37 -> 4591666.7 | G41: =G39+G37 -> 4744722.2 | H41: =H39+H37 -> 4744722.2 | I41: =I39+I37 -> 4438611.1 | ... DQ41: =DQ39+DQ37 -> 17107419
A42: Closing Balance | B42: =B36-B39 -> 580000000 | C42: =C36-C39 -> 580000000 | D42: =D36-D39 -> 580000000 | E42: =E36-E39 -> 580000000 | F42: =F36-F39 -> 580000000 | G42: =G36-G39 -> 580000000 | H42: =H36-H39 -> 580000000 | I42: =I36-I39 -> 580000000 | ... DQ42: =DQ36-DQ39 -> 0
DQ43: =+DQ38-SCBL_Loan!AO44 -> 0
A44: Disbursement-1 (b)
A45: Period
A46: Expected Interest Rate | B46: =+B34 -> 0.095 | C46: =+C34 -> 0.095 | D46: =+D34 -> 0.095 | E46: =+E34 -> 0.095 | F46: =+F34 -> 0.095 | G46: =+G34 -> 0.095 | H46: =+H34 -> 0.095 | I46: =+I34 -> 0.095 | ... DQ46: =+DQ34 -> 0.09
A47: Months | B47: =B35 -> 43678 | C47: =EDATE(B47,1) -> 43709 | D47: =EDATE(C47,1) -> 43739 | E47: =EDATE(D47,1) -> 43770 | F47: =EDATE(E47,1) -> 43800 | G47: =EDATE(F47,1) -> 43831 | H47: =EDATE(G47,1) -> 43862 | I47: =EDATE(H47,1) -> 43891 | J47: =EDATE(I47,1) -> 43922 | ... DQ47: =EDATE(DP47,1) -> 47300
A48: Opening Balance | B48: =D16 -> 120000000 | C48: =B54 -> 120000000 | D48: =C54 -> 120000000 | E48: =D54 -> 120000000 | F48: =E54 -> 120000000 | G48: =F54 -> 120000000 | H48: =G54 -> 120000000 | I48: =H54 -> 120000000 | J48: =I54 -> 120000000 | ... DQ48: =DP54 -> 3528000
A49: Interest Payment | B49: =B48*(B47-D15)*B46/360 -> 950000 | C49: =C48*(C47-B47)*C46/360 -> 981666.67 | D49: =D48*(D47-C47)*D46/360 -> 950000 | E49: =E48*(E47-D47)*E46/360 -> 981666.67 | F49: =F48*(F47-E47)*F46/360 -> 950000 | G49: =G48*(G47-F47)*G46/360 -> 981666.67 | H49: =H48*(H47-G47)*H46/360 -> 981666.67 | I49: =I48*(I47-H47)*I46/360 -> 918333.33 | J49: =J48*(SCBL_Loan!$D$54-I47)*I46/360+J54*(J47-SCBL_Loan!$D$54)*J46/360 -> 981666.67 | K49: =K48*(K47-J47)*K46/360 -> 950000 | L49: =L48*(L47-K47)*L46/360 -> 981666.67 | M49: =M48*(M47-L47)*M46/360 -> 950000 | N49: =N48*(N47-M47)*N46/360 -> 981666.67 | O49: =O48*($O$32-N47)*N46/360+O48*(O47-$O$32)*O46/360 -> 950000 | P49: =P48*(P47-O47)*P46/360 -> 900000 | Q49: =Q48*(Q47-P47)*Q46/360 -> 930000 | R49: =R48*(R47-Q47)*R46/360 -> 900000 | S49: =S48*(SCBL_Loan!$G$28-R47)*R46/360+S54*(S47-SCBL_Loan!$G$28)*S46/360 -> 930000 | T49: =T48*(T47-S47)*T46/360 -> 930000 | U49: =U48*(U47-T47)*U46/360 -> 840000 | V49: =V48*(SCBL_Loan!$H$28-U47)*U46/360+V54*(V47-SCBL_Loan!$H$28)*V46/360 -> 914904 | W49: =W48*(W47-V47)*W46/360 -> 873360 | X49: =X48*(X47-W47)*X46/360 -> 902472 | Y49: =Y48*(SCBL_Loan!$I$28-X47)*X46/360+Y54*(Y47-SCBL_Loan!$I$28)*Y46/360 -> 859152 | Z49: =Z48*(Z47-Y47)*Z46/360 -> 874944 | AA49: =AA48*(AA47-Z47)*AA46/360 -> 874944 | AB49: =AB48*(SCBL_Loan!$J$28-AA47)*AA46/360+AB54*(AB47-SCBL_Loan!$J$28)*AB46/360 -> 832608 | AC49: =AC48*(AC47-AB47)*AC46/360 -> 847602 | AD49: =AD48*(AD47-AC47)*AD46/360 -> 820260 | AE49: =AE48*(SCBL_Loan!$K$28-AD47)*AD46/360+AE54*(AE47-SCBL_Loan!$K28)*AE46/360 -> 832608 | AF49: =AF48*(AF47-AE47)*AF46/360 -> 820260 | AG49: =AG48*(AG47-AF47)*AG46/360 -> 740880 | AH49: =AH48*(SCBL_Loan!$L$28-AG47)*AG46/360+AH54*(AH47-SCBL_Loan!$L$28)*AH46/360 -> 805266 | AI49: =AI48*(AI47-AH47)*AI46/360 -> 767340 | AJ49: =AJ48*(AJ47-AI47)*AJ46/360 -> 792918 | AK49: =AK48*(SCBL_Loan!$M$28-AJ47)*AJ46/360+AK54*(AK47-SCBL_Loan!$M$28)*AK46/360 -> 753228 | AL49: =AL48*(AL47-AK47)*AL46/360 -> 765576 | AM49: =AM48*(AM47-AL47)*AM46/360 -> 765576 | AN49: =AN48*(SCBL_Loan!$N$28-AM47)*AM46/360+AN54*(AN47-SCBL_Loan!$N$28)*AN46/360 -> 726768 | AO49: =AO48*(AO47-AN47)*AO46/360 -> 738234 | AP49: =AP48*(AP47-AO47)*AP46/360 -> 714420 | AQ49: =AQ48*(SCBL_Loan!$O$28-AP47)*AP46/360+AQ54*(AQ47-SCBL_Loan!$O$28)*AQ46/360 -> 723240 | AR49: =AR48*(AR47-AQ47)*AR46/360 -> 710892 | AS49: =AS48*(AS47-AR47)*AS46/360 -> 642096 | AT49: =AT48*(SCBL_Loan!$P$28-AS47)*AS46/360+AT54*(AT47-SCBL_Loan!$P$28)*AT46/360 -> 695898 | AU49: =AU48*(AU47-AT47)*AU46/360 -> 661500 | AV49: =AV48*(AV47-AU47)*AV46/360 -> 683550 | AW49: =AW48*(SCBL_Loan!$Q$28-AV47)*AV46/360+AW54*(AW47-SCBL_Loan!$Q$28)*AW46/360 -> 647388 | AX49: =AX48*(AX47-AW47)*AX46/360 -> 656208 | AY49: =AY48*(AY47-AX47)*AY46/360 -> 656208 | AZ49: =AZ48*(SCBL_Loan!$R$28-AY47)*AY46/360+AZ54*(AZ47-SCBL_Loan!$R$28)*AZ46/360 -> 620046 | BA49: =BA48*(BA47-AZ47)*BA46/360 -> 628866 | BB49: =BB48*(BB47-BA47)*BB46/360 -> 608580 | BC49: =BC48*(SCBL_Loan!$S$28-BB47)*BB46/360+BC54*(BC47-SCBL_Loan!$S$28)*BC46/360 -> 612990 | BD49: =BD48*(BD47-BC47)*BD46/360 -> 601524 | BE49: =BE48*(BE47-BD47)*BE46/360 -> 562716 | BF49: =BF48*(SCBL_Loan!$T$28-BE47)*BE46/360+BF54*(BF47-SCBL_Loan!$T$28)*BF46/360 -> 585648 | BG49: =BG48*(BG47-BF47)*BG46/360 -> 555660 | BH49: =BH48*(BH47-BG47)*BH46/360 -> 574182 | BI49: =BI48*(SCBL_Loan!$U$28-BH47)*BH46/360+BI54*(BI47-SCBL_Loan!$U$28)*BI46/360 -> 539784 | BJ49: =BJ48*(BJ47-BI47)*BJ46/360 -> 546840 | BK49: =BK48*(BK47-BJ47)*BK46/360 -> 546840 | BL49: =BL48*(SCBL_Loan!$V$28-BK47)*BK46/360+BL54*(BL47-SCBL_Loan!$V$28)*BL46/360 -> 515088 | BM49: =BM48*(BM47-BL47)*BM46/360 -> 519498 | BN49: =BN48*(BN47-BM47)*BN46/360 -> 502740 | BO49: =BO48*(SCBL_Loan!$W$28-BN47)*BN46/360+BO54*(BO47-SCBL_Loan!$W$28)*BO46/360 -> 504504 | BP49: =BP48*(BP47-BO47)*BP46/360 -> 492156 | BQ49: =BQ48*(BQ47-BP47)*BQ46/360 -> 444528 | BR49: =BR48*(SCBL_Loan!$X$28-BQ47)*BQ46/360+BR54*(BR47-SCBL_Loan!$X$28)*BR46/360 -> 475398 | BS49: =BS48*(BS47-BR47)*BS46/360 -> 449820 | BT49: =BT48*(BT47-BS47)*BT46/360 -> 464814 | BU49: =BU48*(SCBL_Loan!$Y$28-BT47)*BT46/360+BU54*(BU47-SCBL_Loan!$Y$28)*BU46/360 -> 435708 | BV49: =BV48*(BV47-BU47)*BV46/360 -> 437472 | BW49: =BW48*(BW47-BV47)*BW46/360 -> 437472 | BX49: =BX48*(SCBL_Loan!$Z$28-BW47)*BW46/360+BX54*(BX47-SCBL_Loan!$Z$28)*BX46/360 -> 409248 | BY49: =BY48*(BY47-BX47)*BY46/360 -> 410130 | BZ49: =BZ48*(BZ47-BY47)*BZ46/360 -> 396900 | CA49: =CA48*(SCBL_Loan!$AA$28-BZ47)*BZ46/360+CA54*(CA47-SCBL_Loan!$AA$28)*CA46/360 -> 395136 | CB49: =CB48*(CB47-CA47)*CB46/360 -> 382788 | CC49: =CC48*(CC47-CB47)*CC46/360 -> 345744 | CD49: =CD48*(SCBL_Loan!$AB$28-CC47)*CC46/360+CD54*(CD47-SCBL_Loan!$AB$28)*CD46/360 -> 367794 | CE49: =CE48*(CE47-CD47)*CE46/360 -> 343980 | CF49: =CF48*(CF47-CE47)*CF46/360 -> 355446 | CG49: =CG48*(SCBL_Loan!$AC$28-CF47)*CF46/360+CG54*(CG47-SCBL_Loan!$AC$28)*CG46/360 -> 329868 | CH49: =CH48*(CH47-CG47)*CH46/360 -> 328104 | CI49: =CI48*(CI47-CH47)*CI46/360 -> 328104 | CJ49: =CJ48*(SCBL_Loan!$AD$28-CI47)*CI46/360+CJ54*(CJ47-SCBL_Loan!$AD$28)*CJ46/360 -> 303408 | CK49: =CK48*(CK47-CJ47)*CK46/360 -> 300762 | CL49: =CL48*(CL47-CK47)*CL46/360 -> 291060 | CM49: =CM48*(SCBL_Loan!$AE$28-CL47)*CL46/360+CM54*(CM47-SCBL_Loan!$AE$28)*CM46/360 -> 285768 | CN49: =CN48*(CN47-CM47)*CN46/360 -> 273420 | CO49: =CO48*(CO47-CN47)*CO46/360 -> 246960 | CP49: =CP48*(SCBL_Loan!$AF$28-CO47)*CO46/360+CP54*(CP47-SCBL_Loan!$AF$28)*CP46/360 -> 258426 | CQ49: =CQ48*(CQ47-CP47)*CQ46/360 -> 238140 | CR49: =CR48*(CR47-CQ47)*CR46/360 -> 246078 | CS49: =CS48*(SCBL_Loan!$AG$28-CR47)*CR46/360+CS54*(CS47-SCBL_Loan!$AG$28)*CS46/360 -> 224028 | CT49: =CT48*(CT47-CS47)*CT46/360 -> 218736 | CU49: =CU48*(CU47-CT47)*CU46/360 -> 218736 | CV49: =CV48*(SCBL_Loan!$AH$28-CU47)*CU46/360+CV54*(CV47-SCBL_Loan!$AH$28)*CV46/360 -> 197568 | CW49: =CW48*(CW47-CV47)*CW46/360 -> 191394 | CX49: =CX48*(CX47-CW47)*CX46/360 -> 185220 | CY49: =CY48*(SCBL_Loan!$AI$28-CX47)*CX46/360+CY54*(CY47-SCBL_Loan!$AI$28)*CY46/360 -> 176400 | CZ49: =CZ48*(CZ47-CY47)*CZ46/360 -> 164052 | DA49: =DA48*(DA47-CZ47)*DA46/360 -> 153468 | DB49: =DB48*(SCBL_Loan!$AJ$28-DA47)*DA46/360+DB54*(DB47-SCBL_Loan!$AJ$28)*DB46/360 -> 149058 | DC49: =DC48*(DC47-DB47)*DC46/360 -> 132300 | DD49: =DD48*(DD47-DC47)*DD46/360 -> 136710 | DE49: =DE48*(SCBL_Loan!$AK$28-DD47)*DD46/360+DE54*(DE47-SCBL_Loan!$AK$28)*DE46/360 -> 118188 | DF49: =DF48*(DF47-DE47)*DF46/360 -> 109368 | DG49: =DG48*(DG47-DF47)*DG46/360 -> 109368 | DH49: =DH48*(SCBL_Loan!$AL$28-DG47)*DG46/360+DH54*(DH47-SCBL_Loan!$AL$28)*DH46/360 -> 90846 | DI49: =DI48*(DI47-DH47)*DI46/360 -> 82026 | DJ49: =DJ48*(DJ47-DI47)*DJ46/360 -> 79380 | DK49: =DK48*(SCBL_Loan!$AM$28-DJ47)*DJ46/360+DK54*(DK47-SCBL_Loan!$AM$28)*DK46/360 -> 66150 | DL49: =DL48*(DL47-DK47)*DL46/360 -> 54684 | DM49: =DM48*(DM47-DL47)*DM46/360 -> 49392 | DN49: =DN48*(SCBL_Loan!$AN$28-DM47)*DM46/360+DN54*(DN47-SCBL_Loan!$AN$28)*DN46/360 -> 39690 | DO49: =DO48*(DO47-DN47)*DO46/360 -> 26460 | DP49: =DP48*(DP47-DO47)*DP46/360 -> 27342 | DQ49: =DQ48*(SCBL_Loan!$AO$28-DP47)*DP46/360+DQ54*(DQ47-SCBL_Loan!$AO$28)*DQ46/360 -> 11466
...

Sheet Repayment Schedule
A1: Project name: | C1: =SCBL_Loan!C1 -> Seven Circle (Bangladesh) Ltd.
A3: Financial Close | C3: =SCBL_Loan!C3 -> 43626
A5: Loan Amount | C5: =SCBL_Loan!C5 -> 1700000000
A7: Interest Rate | C7: =SCBL_Loan!C8 -> 0.095
A9: Number of installments | C9: =SCBL_Loan!C13 -> 34
A11: Drawdown (IDCOL)
C12: =SCBL_Loan!C16 -> 43648 | D12: =SCBL_Loan!D16 -> 43648 | E12: =SCBL_Loan!E16 -> 43662
C13: =SCBL_Loan!C17 -> 580000000 | D13: =SCBL_Loan!D17 -> 120000000 | E13: =SCBL_Loan!E17 -> 1000000000
C14: =C13 -> 580000000 | D14: =C14+D13 -> 700000000 | E14: =D14+E13 -> 1700000000
A16: {=TRANSPOSE(SCBL_Loan!A28:AO35)} -> Repayment Date | B16: Opening Balance | C16: Interest Payment | D16: Cumulative interest | E16: Principal Payment | F16: Cumulative repayment | G16: Total Debt Service | H16: Closing Balance
A17: 43723 | B17: 1700000000 | C17: 29951389 | D17: 29951389 | E17: 0 | F17: 0 | G17: 29951389 | H17: 1700000000 | K17: 29951389 | L17: =+C17-K17 -> -0.0011111125 | M17: 0 | N17: =+M17-E17 -> 0
A18: 43814 | B18: 1700000000 | C18: 40823611 | D18: 70775000 | E18: 0 | F18: 0 | G18: 40823611 | H18: 1700000000 | K18: 40823611 | L18: =+C18-K18 -> 0.0011111125 | M18: 0 | N18: =+M18-E18 -> 0
A19: 43905 | B19: 1700000000 | C19: 40823611 | D19: 1.1159861e+08 | E19: 0 | F19: 0 | G19: 40823611 | H19: 1700000000 | K19: 40823611 | L19: =+C19-K19 -> 0.0011111125 | M19: 0 | N19: =+M19-E19 -> 0
A20: 43997 | B20: 1700000000 | C20: 41272222 | D20: 1.5287083e+08 | E20: 0 | F20: 0 | G20: 41272222 | H20: 1700000000 | K20: 41272222 | L20: =+C20-K20 -> 0.0022222251 | M20: 0 | N20: =+M20-E20 -> 0
A21: 44089 | B21: 1700000000 | C21: 40493056 | D21: 1.9336389e+08 | E21: 0 | F21: 0 | G21: 40493056 | H21: 1700000000 | K21: 40493056 | L21: =+C21-K21 -> -0.0044444501 | M21: 0 | N21: =+M21-E21 -> 0
A22: 44180 | B22: 1700000000 | C22: 38675000 | D22: 2.3203889e+08 | E22: 0 | F22: 0 | G22: 38675000 | H22: 1700000000 | K22: 38675000 | L22: =+C22-K22 -> 0 | M22: 0 | N22: =+M22-E22 -> 0
A23: 44270 | B23: 1700000000 | C23: 38250000 | D23: 2.7028889e+08 | E23: 50320000 | F23: 50320000 | G23: 88570000 | H23: 1649680000 | K23: 38250000 | L23: =+C23-K23 -> 0 | M23: 50320000 | N23: =+M23-E23 -> 0
A24: 44362 | B24: 1649680000 | C24: 37942640 | D24: 3.0823153e+08 | E24: 50320000 | F24: 100640000 | G24: 88262640 | H24: 1599360000 | K24: 37942640 | L24: =+C24-K24 -> 0 | M24: 50320000 | N24: =+M24-E24 -> 0
A25: 44454 | B25: 1599360000 | C25: 36785280 | D25: 3.4501681e+08 | E25: 49980000 | F25: 150620000 | G25: 86765280 | H25: 1549380000 | K25: 36785280 | L25: =+C25-K25 -> 0 | M25: 49980000 | N25: =+M25-E25 -> 0
A26: 44545 | B26: 1549380000 | C26: 35248395 | D26: 3.802652e+08 | E26: 49980000 | F26: 200600000 | G26: 85228395 | H26: 1499400000 | K26: 35248395 | L26: =+C26-K26 -> 0 | M26: 49980000 | N26: =+M26-E26 -> 0
A27: 44635 | B27: 1499400000 | C27: 33736500 | D27: 4.140017e+08 | E27: 49980000 | F27: 250580000 | G27: 83716500 | H27: 1449420000 | K27: 33736500 | L27: =+C27-K27 -> 0 | M27: 49980000 | N27: =+M27-E27 -> 0
A28: 44727 | B28: 1449420000 | C28: 33336660 | D28: 4.4733836e+08 | E28: 49980000 | F28: 300560000 | G28: 83316660 | H28: 1399440000 | K28: 33336660 | L28: =+C28-K28 -> 0 | M28: 49980000 | N28: =+M28-E28 -> 0
... A56: 47283 | B56: 49980000 | C56: 1137045 | D56: 9.1051552e+08 | E56: 49980000 | F56: 1700000000 | G56: 51117045 | H56: 0 | K56: 1137045 | L56: =+C56-K56 -> 0 | M56: 49980000 | N56: =+M56-E56 -> 0
